<mujoco>
  <option gravity="0 0 0" />
  <worldbody>
    <light diffuse=".5 .5 .5" pos="0 0 10" dir="0 0 -1"/>
    <geom type="plane" size="6 4 0.1" rgba="1 1 1 1"/>

    <body pos="0.5 0 0.06" euler="-90 90 90">
      <joint name="1" type="hinge" axis="-1 0 0" pos="0 0 -0.866" damping="1" stiffness="0.8"/>
      <geom type="cylinder" size="0.06 0.866" rgba="1 0 0 1" mass="0.1"/>
      <body pos="0 0 1.366" euler="0 0 0">
        <joint name="2" type="hinge" axis="-1 0 0" pos="0 0 -0.5" damping="20" stiffness="0.5"/>
        <geom type="capsule" fromto="0 0 0.5 0 0 -0.5" size="0.06" friction = "0.8" rgba="0 1 0 1" mass="0.1"/>
        
      </body>
    </body>

    
    <!-- Cylinder (outer) -->
    <body pos="-2.5 2 0.1" euler="-90 90 90">
    <joint name="3" type="hinge" axis="-1 0 0" pos="0 0 -0.5" damping="0.01" stiffness="0.01"/>
      <geom type="cylinder" size="0.1 0.5" rgba="0.7 0.7 0.7 0.3" mass="0.3"/> 
      <site name="cylinder_base" pos="0 0 -0.5" size="0.01"/> 
      
      <!-- Piston (inner) -->
      <body pos="0 0 1.5">
        <joint name="piston_joint" type="slide" axis="0 0 1" pos="0 0 0" damping="3" stiffness="1"/>
        <geom type="cylinder" size="0.09 0.4" rgba="0 0 0.2 1" friction = "0.8" mass="0.2"/> 
        <site name="piston_tip" size="0.05" pos="0 0 -0.4"/> 
        <site name = "force_sensor" size= "0.08" pos="0 0 0.4"/>
      </body>
    </body>
  </worldbody>
  


  
  <tendon>
    <spatial name="spring_tendon"  width="0.02" rgba="0.9 0.9 0.1 1" stiffness="50" damping="0.01" range="0 0.8">
      <site site="cylinder_base"/> 
      <site site="piston_tip"/> 
    </spatial>
  </tendon>

  <sensor>
    <force name="my_force_sensor" site="force_sensor"/>
 </sensor>
  
  <actuator>
    <motor name="link1" joint="1" ctrllimited="true" ctrlrange="-20 20"/> 
    <motor name="link2" joint="2" ctrllimited="true" ctrlrange="-20 20"/>
    <motor name="link3" joint="3" ctrllimited="true" ctrlrange="-20 20"/> 
    <motor name="piston_motor" joint="piston_joint" ctrllimited="true" ctrlrange="-0.4 0.4"/> 
  </actuator>
</mujoco>

